Workbook

Sheet Dashboard
A1: ESP32-S3 Solo Program Dashboard
A3: Project Start | B3: =Control!B6 -> 46216 | D3: Reporting Week | E3: =Control!B7 -> 1 | G3: Production Release Week | H3: =Control!B8 -> 78
A5: Planned Completion | B5: =Control!B10 -> 0.010899183 | D5: Actual Completion | E5: =Control!B11 -> 0.11553134 | G5: Schedule Variance | H5: =Control!B12 -> 0.10463215
A7: Late Tasks | B7: =Control!B13 -> 0 | D7: Completed Tasks | E7: =Control!B14 -> 15 | G7: Total Work Packages | H7: =Control!B15 -> 133
A11: Cluster | B11: Name | C11: Start | D11: End | E11: Planned % | F11: Actual % | G11: Variance | H11: Tasks | I11: Complete | J11: Late | K11: Gate
A12: A | B12: Product Definition and Planning | C12: 1 | D12: 6 | E12: =IFERROR(SUMIF(WBS!$B$5:$B$137,A12,WBS!$S$5:$S$137)/SUMIF(WBS!$B$5:$B$137,A12,WBS!$R$5:$R$137),0) -> 0.13157895 | F12: =IFERROR(SUMIF(WBS!$B$5:$B$137,A12,WBS!$T$5:$T$137)/SUMIF(WBS!$B$5:$B$137,A12,WBS!$R$5:$R$137),0) -> 1 | G12: =F12-E12 -> 0.86842105 | H12: =COUNTIF(WBS!$B$5:$B$137,A12) -> 10 | I12: =COUNTIFS(WBS!$B$5:$B$137,A12,WBS!$U$5:$U$137,"Complete") -> 10 | J12: =COUNTIFS(WBS!$B$5:$B$137,A12,WBS!$U$5:$U$137,"Late") -> 0 | K12: G-A
A13: B | B13: Engineering Foundation | C13: 7 | D13: 12 | E13: =IFERROR(SUMIF(WBS!$B$5:$B$137,A13,WBS!$S$5:$S$137)/SUMIF(WBS!$B$5:$B$137,A13,WBS!$R$5:$R$137),0) -> 0 | F13: =IFERROR(SUMIF(WBS!$B$5:$B$137,A13,WBS!$T$5:$T$137)/SUMIF(WBS!$B$5:$B$137,A13,WBS!$R$5:$R$137),0) -> 0.37037037 | G13: =F13-E13 -> 0.37037037 | H13: =COUNTIF(WBS!$B$5:$B$137,A13) -> 12 | I13: =COUNTIFS(WBS!$B$5:$B$137,A13,WBS!$U$5:$U$137,"Complete") -> 5 | J13: =COUNTIFS(WBS!$B$5:$B$137,A13,WBS!$U$5:$U$137,"Late") -> 0 | K13: G-B
A14: C | B14: Platform and Architecture Development | C14: 13 | D14: 34 | E14: =IFERROR(SUMIF(WBS!$B$5:$B$137,A14,WBS!$S$5:$S$137)/SUMIF(WBS!$B$5:$B$137,A14,WBS!$R$5:$R$137),0) -> 0 | F14: =IFERROR(SUMIF(WBS!$B$5:$B$137,A14,WBS!$T$5:$T$137)/SUMIF(WBS!$B$5:$B$137,A14,WBS!$R$5:$R$137),0) -> 0 | G14: =F14-E14 -> 0 | H14: =COUNTIF(WBS!$B$5:$B$137,A14) -> 32 | I14: =COUNTIFS(WBS!$B$5:$B$137,A14,WBS!$U$5:$U$137,"Complete") -> 0 | J14: =COUNTIFS(WBS!$B$5:$B$137,A14,WBS!$U$5:$U$137,"Late") -> 0 | K14: G-C
A15: D | B15: Product Feature Development | C15: 35 | D15: 56 | E15: =IFERROR(SUMIF(WBS!$B$5:$B$137,A15,WBS!$S$5:$S$137)/SUMIF(WBS!$B$5:$B$137,A15,WBS!$R$5:$R$137),0) -> 0 | F15: =IFERROR(SUMIF(WBS!$B$5:$B$137,A15,WBS!$T$5:$T$137)/SUMIF(WBS!$B$5:$B$137,A15,WBS!$R$5:$R$137),0) -> 0 | G15: =F15-E15 -> 0 | H15: =COUNTIF(WBS!$B$5:$B$137,A15) -> 33 | I15: =COUNTIFS(WBS!$B$5:$B$137,A15,WBS!$U$5:$U$137,"Complete") -> 0 | J15: =COUNTIFS(WBS!$B$5:$B$137,A15,WBS!$U$5:$U$137,"Late") -> 0 | K15: G-D
A16: E | B16: Verification and Qualification | C16: 57 | D16: 70 | E16: =IFERROR(SUMIF(WBS!$B$5:$B$137,A16,WBS!$S$5:$S$137)/SUMIF(WBS!$B$5:$B$137,A16,WBS!$R$5:$R$137),0) -> 0 | F16: =IFERROR(SUMIF(WBS!$B$5:$B$137,A16,WBS!$T$5:$T$137)/SUMIF(WBS!$B$5:$B$137,A16,WBS!$R$5:$R$137),0) -> 0 | G16: =F16-E16 -> 0 | H16: =COUNTIF(WBS!$B$5:$B$137,A16) -> 20 | I16: =COUNTIFS(WBS!$B$5:$B$137,A16,WBS!$U$5:$U$137,"Complete") -> 0 | J16: =COUNTIFS(WBS!$B$5:$B$137,A16,WBS!$U$5:$U$137,"Late") -> 0 | K16: G-E
A17: F | B17: Industrialization and Production Release | C17: 71 | D17: 78 | E17: =IFERROR(SUMIF(WBS!$B$5:$B$137,A17,WBS!$S$5:$S$137)/SUMIF(WBS!$B$5:$B$137,A17,WBS!$R$5:$R$137),0) -> 0 | F17: =IFERROR(SUMIF(WBS!$B$5:$B$137,A17,WBS!$T$5:$T$137)/SUMIF(WBS!$B$5:$B$137,A17,WBS!$R$5:$R$137),0) -> 0 | G17: =F17-E17 -> 0 | H17: =COUNTIF(WBS!$B$5:$B$137,A17) -> 12 | I17: =COUNTIFS(WBS!$B$5:$B$137,A17,WBS!$U$5:$U$137,"Complete") -> 0 | J17: =COUNTIFS(WBS!$B$5:$B$137,A17,WBS!$U$5:$U$137,"Late") -> 0 | K17: G-F
A18: G | B18: Field Operation and Lifecycle Maintenance | C18: 79 | D18: 90 | E18: =IFERROR(SUMIF(WBS!$B$5:$B$137,A18,WBS!$S$5:$S$137)/SUMIF(WBS!$B$5:$B$137,A18,WBS!$R$5:$R$137),0) -> 0 | F18: =IFERROR(SUMIF(WBS!$B$5:$B$137,A18,WBS!$T$5:$T$137)/SUMIF(WBS!$B$5:$B$137,A18,WBS!$R$5:$R$137),0) -> 0 | G18: =F18-E18 -> 0 | H18: =COUNTIF(WBS!$B$5:$B$137,A18) -> 14 | I18: =COUNTIFS(WBS!$B$5:$B$137,A18,WBS!$U$5:$U$137,"Complete") -> 0 | J18: =COUNTIFS(WBS!$B$5:$B$137,A18,WBS!$U$5:$U$137,"Late") -> 0 | K18: G-G
A21: Current Gate Logic and Assumptions
A22: One owner means every row is assigned to “Me”. Overlapping rows are intended to be interleaved within the same week.
A23: Task Actual Completion starts at 0% because no execution evidence was provided. Enter evidence-based progress only.
A24: A cluster gate is accepted only when its gate row reaches 100% and the stated completion criteria are met.
A25: Week 78 is the production release baseline. Weeks 79–90 cover staged rollout, stabilization, upgrades, hardware support and closure readiness.

Sheet Control
A1: ESP32-S3 Solo Project WBS — Control
A3: Field | B3: Value | C3: Purpose | D3: Editable?
A4: Project Name | B4: ESP32-S3 Production Firmware Program | C4: Program tracked by this workbook | D4: Yes
A5: Owner | B5: Parthasarathy CP | C5: Single accountable owner for every work package | D5: Yes
A6: Project Start | B6: 46216 | C6: Monday used to derive weekly dates | D6: Yes
A7: Reporting Week | B7: 1 | C7: Update this value from 1 to 90 for planned-progress/status calculations | D7: Yes
A8: Production Release Week | B8: 78 | C8: Cluster F production release baseline | D8: No
A9: Lifecycle Baseline End Week | B9: 90 | C9: Initial field stabilization and lifecycle closure horizon | D9: No
A10: Overall Planned Completion | B10: =SUM(WBS!S5:S137) -> 0.010899183 | C10: Weighted planned progress at Reporting Week | D10: Formula
A11: Overall Actual Completion | B11: =SUM(WBS!T5:T137) -> 0.11553134 | C11: Weighted sum of task Actual Completion values | D11: Formula
A12: Schedule Variance | B12: =B11-B10 -> 0.10463215 | C12: Actual minus planned | D12: Formula
A13: Late Tasks | B13: =COUNTIF(WBS!U5:U137,"Late") -> 0 | C13: Zero-progress tasks whose end week is before Reporting Week | D13: Formula
A14: Completed Tasks | B14: =COUNTIF(WBS!U5:U137,"Complete") -> 15 | C14: Tasks at 100% | D14: Formula
A15: Total Work Packages | B15: =COUNTA(WBS!A5:A137) -> 133 | C15: Detailed WBS rows | D15: Formula
A17: Progress Update Method
A18: 1 | B18: Set Reporting Week in B7.
A19: 2 | B19: Update WBS column Q (Actual Completion %) using the dropdown.
A20: 3 | B20: Store links or file paths to evidence in WBS column X (Notes).
A21: 4 | B21: Review Dashboard variances, late tasks and cluster gates.

Sheet WBS
A1: ESP32-S3 Production Firmware Program — Detailed Work Breakdown Structure
A2: Baseline: 90 weeks, one owner. Update Actual Completion % and evidence links; all other progress fields calculate automatically.
A4: WBS ID | B4: Cluster | C4: Cluster Name | D4: Phase | E4: Phase Name | F4: Weekly Activity / Work Package | G4: Dependencies | H4: Start Week | I4: End Week | J4: Duration (wks) | K4: Effort Points | L4: Owner | M4: Evidence / Deliverable | N4: Completion Criteria | O4: Gate | P4: Planned Progress % | Q4: Actual Completion % | R4: Weight % | S4: Planned Contribution % | T4: Actual Contribution % | U4: Status | V4: Planned Start | W4: Planned Finish | X4: Notes / Evidence Link
A5: A1.1 | B5: A | C5: Product Definition and Planning | D5: A1 | E5: Product concept definition | F5: Define users, operating environment, installation, power, connectivity, UI, maintenance and update strategy | H5: 1 | I5: 1 | J5: 1 | K5: 1 | L5: Me | M5: Product concept document and primary use-case list | N5: All primary users, operating modes and maintenance assumptions documented | P5: =IF(Control!$B$7<H5,0,IF(Control!$B$7>=I5,1,(Control!$B$7-H5+1)/J5)) -> 1 | Q5: 1 | R5: =K5/SUM($K$5:$K$137) -> 0.0054495913 | S5: =P5*R5 -> 0.0054495913 | T5: =Q5*R5 -> 0.0054495913 | U5: =IF(Q5>=1,"Complete",IF(Q5>0,"In Progress",IF(Control!$B$7<H5,"Not Started",IF(Control!$B$7>I5,"Late","Ready")))) -> Complete | V5: 46216 | W5: 46222
A6: A1.2 | B6: A | C6: Product Definition and Planning | D6: A1 | E6: Product concept definition | F6: Model normal and abnormal operating scenarios | G6: A1.1 | H6: 1 | I6: 2 | J6: 2 | K6: 2 | L6: Me | M6: Normal/abnormal scenario catalogue | N6: Every expected device mode and principal failure scenario has defined behavior | P6: =IF(Control!$B$7<H6,0,IF(Control!$B$7>=I6,1,(Control!$B$7-H6+1)/J6)) -> 0.5 | Q6: 1 | R6: =K6/SUM($K$5:$K$137) -> 0.010899183 | S6: =P6*R6 -> 0.0054495913 | T6: =Q6*R6 -> 0.010899183 | U6: =IF(Q6>=1,"Complete",IF(Q6>0,"In Progress",IF(Control!$B$7<H6,"Not Started",IF(Control!$B$7>I6,"Late","Ready")))) -> Complete | V6: 46216 | W6: 46229
A7: A1.3 | B7: A | C7: Product Definition and Planning | D7: A1 | E7: Product concept definition | F7: Define firmware, cloud, mobile, factory and recovery boundaries | G7: A1.1 | H7: 2 | I7: 2 | J7: 1 | K7: 1 | L7: Me | M7: System context diagram and product-boundary document | N7: Responsibilities are separated with no ambiguous ownership | P7: =IF(Control!$B$7<H7,0,IF(Control!$B$7>=I7,1,(Control!$B$7-H7+1)/J7)) -> 0 | Q7: 1 | R7: =K7/SUM($K$5:$K$137) -> 0.0054495913 | S7: =P7*R7 -> 0 | T7: =Q7*R7 -> 0.0054495913 | U7: =IF(Q7>=1,"Complete",IF(Q7>0,"In Progress",IF(Control!$B$7<H7,"Not Started",IF(Control!$B$7>I7,"Late","Ready")))) -> Complete | V7: 46223 | W7: 46229
A8: A2.1 | B8: A | C8: Product Definition and Planning | D8: A2 | E8: Requirements engineering | F8: Write uniquely identified functional requirements | G8: A1.2,A1.3 | H8: 2 | I8: 3 | J8: 2 | K8: 2 | L8: Me | M8: System requirements specification with FR identifiers | N8: Each function is measurable and traceable | P8: =IF(Control!$B$7<H8,0,IF(Control!$B$7>=I8,1,(Control!$B$7-H8+1)/J8)) -> 0 | Q8: 1 | R8: =K8/SUM($K$5:$K$137) -> 0.010899183 | S8: =P8*R8 -> 0 | T8: =Q8*R8 -> 0.010899183 | U8: =IF(Q8>=1,"Complete",IF(Q8>0,"In Progress",IF(Control!$B$7<H8,"Not Started",IF(Control!$B$7>I8,"Late","Ready")))) -> Complete | V8: 46223 | W8: 46236
A9: A2.2 | B9: A | C9: Product Definition and Planning | D9: A2 | E9: Requirements engineering | F9: Set measurable non-functional budgets for timing, memory, power, availability and security | G9: A2.1 | H9: 3 | I9: 3 | J9: 1 | K9: 1 | L9: Me | M9: Non-functional requirements specification | N9: Every NFR has a numeric target and test method | P9: =IF(Control!$B$7<H9,0,IF(Control!$B$7>=I9,1,(Control!$B$7-H9+1)/J9)) -> 0 | Q9: 1 | R9: =K9/SUM($K$5:$K$137) -> 0.0054495913 | S9: =P9*R9 -> 0 | T9: =Q9*R9 -> 0.0054495913 | U9: =IF(Q9>=1,"Complete",IF(Q9>0,"In Progress",IF(Control!$B$7<H9,"Not Started",IF(Control!$B$7>I9,"Late","Ready")))) -> Complete | V9: 46230 | W9: 46236
A10: A2.3 | B10: A | C10: Product Definition and Planning | D10: A2 | E10: Requirements engineering | F10: Define hardware, communications, diagnostics, manufacturing and OTA interfaces plus environmental constraints | G10: A2.1 | H10: 3 | I10: 4 | J10: 2 | K10: 2 | L10: Me | M10: Interface control document and environmental/regulatory checklist | N10: All external and internal interfaces have limits, ownership and error behavior | P10: =IF(Control!$B$7<H10,0,IF(Control!$B$7>=I10,1,(Control!$B$7-H10+1)/J10)) -> 0 | Q10: 1 | R10: =K10/SUM($K$5:$K$137) -> 0.010899183 | S10: =P10*R10 -> 0 | T10: =Q10*R10 -> 0.010899183 | U10: =IF(Q10>=1,"Complete",IF(Q10>0,"In Progress",IF(Control!$B$7<H10,"Not Started",IF(Control!$B$7>I10,"Late","Ready")))) -> Complete | V10: 46230 | W10: 46243
A11: A2.4 | B11: A | C11: Product Definition and Planning | D11: A2 | E11: Requirements engineering | F11: Build requirements traceability matrix and initial acceptance-test list | G11: A2.2,A2.3 | H11: 4 | I11: 4 | J11: 1 | K11: 1 | L11: Me | M11: Requirements traceability matrix and acceptance-test catalogue | N11: Every requirement maps to architecture and a verification method | P11: =IF(Control!$B$7<H11,0,IF(Control!$B$7>=I11,1,(Control!$B$7-H11+1)/J11)) -> 0 | Q11: 1 | R11: =K11/SUM($K$5:$K$137) -> 0.0054495913 | S11: =P11*R11 -> 0 | T11: =Q11*R11 -> 0.0054495913 | U11: =IF(Q11>=1,"Complete",IF(Q11>0,"In Progress",IF(Control!$B$7<H11,"Not Started",IF(Control!$B$7>I11,"Late","Ready")))) -> Complete | V11: 46237 | W11: 46243
A12: A3.1 | B12: A | C12: Product Definition and Planning | D12: A3 | E12: Feasibility and risk analysis | F12: Validate ESP32-S3/Heltec V3 hardware constraints, pins, flash, PSRAM, RF, USB and power controls | G12: A2.3 | H12: 4 | I12: 5 | J12: 2 | K12: 2 | L12: Me | M12: Hardware feasibility report and verified pin/constraint list | N12: Board revision and all critical electrical constraints are confirmed | P12: =IF(Control!$B$7<H12,0,IF(Control!$B$7>=I12,1,(Control!$B$7-H12+1)/J12)) -> 0 | Q12: 1 | R12: =K12/SUM($K$5:$K$137) -> 0.010899183 | S12: =P12*R12 -> 0 | T12: =Q12*R12 -> 0.010899183 | U12: =IF(Q12>=1,"Complete",IF(Q12>0,"In Progress",IF(Control!$B$7<H12,"Not Started",IF(Control!$B$7>I12,"Late","Ready")))) -> Complete | V12: 46237 | W12: 46250
A13: A3.2 | B13: A | C13: Product Definition and Planning | D13: A3 | E13: Feasibility and risk analysis | F13: Prototype high-risk software capabilities: provisioning, LoRaWAN, TLS, OTA, sleep and storage recovery | G13: A3.1 | H13: 5 | I13: 6 | J13: 2 | K13: 2 | L13: Me | M13: Proof-of-concept applications and test logs | N13: Each high-risk assumption is demonstrated on target hardware | P13: =IF(Control!$B$7<H13,0,IF(Control!$B$7>=I13,1,(Control!$B$7-H13+1)/J13)) -> 0 | Q13: 1 | R13: =K13/SUM($K$5:$K$137) -> 0.010899183 | S13: =P13*R13 -> 0 | T13: =Q13*R13 -> 0.010899183 | U13: =IF(Q13>=1,"Complete",IF(Q13>0,"In Progress",IF(Control!$B$7<H13,"Not Started",IF(Control!$B$7>I13,"Late","Ready")))) -> Complete | V13: 46244 | W13: 46257
A14: A3.3 | B14: A | C14: Product Definition and Planning | D14: A3 | E14: Feasibility and risk analysis | F14: Create risk register and preliminary threat model; close Cluster A gate | G14: A2.4,A3.2 | H14: 6 | I14: 6 | J14: 1 | K14: 1.2 | L14: Me | M14: Risk register, threat model and requirements-baseline review record | N14: Risks have mitigations and the requirements baseline is accepted | O14: G-A | P14: =IF(Control!$B$7<H14,0,IF(Control!$B$7>=I14,1,(Control!$B$7-H14+1)/J14)) -> 0 | Q14: 1 | R14: =K14/SUM($K$5:$K$137) -> 0.0065395095 | S14: =P14*R14 -> 0 | T14: =Q14*R14 -> 0.0065395095 | U14: =IF(Q14>=1,"Complete",IF(Q14>0,"In Progress",IF(Control!$B$7<H14,"Not Started",IF(Control!$B$7>I14,"Late","Ready")))) -> Complete | V14: 46251 | W14: 46257
A15: B1.1 | B15: B | C15: Engineering Foundation | D15: B1 | E15: Development environment setup | F15: Install and pin VS Code, ESP-IDF, Git, Python, CMake/Ninja, drivers and debugger support | G15: A3.3 | H15: 7 | I15: 7 | J15: 1 | K15: 1 | L15: Me | M15: Tool-version manifest and installation record | N15: Pinned tools execute successfully on the Windows workstation | P15: =IF(Control!$B$7<H15,0,IF(Control!$B$7>=I15,1,(Control!$B$7-H15+1)/J15)) -> 0 | Q15: 1 | R15: =K15/SUM($K$5:$K$137) -> 0.0054495913 | S15: =P15*R15 -> 0 | T15: =Q15*R15 -> 0.0054495913 | U15: =IF(Q15>=1,"Complete",IF(Q15>0,"In Progress",IF(Control!$B$7<H15,"Not Started",IF(Control!$B$7>I15,"Late","Ready")))) -> Complete | V15: 46258 | W15: 46264
A16: B1.2 | B16: B | C16: Engineering Foundation | D16: B1 | E16: Development environment setup | F16: Build, flash and monitor a minimal ESP32-S3 project from the controlled workspace | G16: B1.1 | H16: 7 | I16: 8 | J16: 2 | K16: 2 | L16: Me | M16: Minimal project binary, flash log and serial monitor capture | N16: Clean build, flash and target execution succeed | P16: =IF(Control!$B$7<H16,0,IF(Control!$B$7>=I16,1,(Control!$B$7-H16+1)/J16)) -> 0 | Q16: 1 | R16: =K16/SUM($K$5:$K$137) -> 0.010899183 | S16: =P16*R16 -> 0 | T16: =Q16*R16 -> 0.010899183 | U16: =IF(Q16>=1,"Complete",IF(Q16>0,"In Progress",IF(Control!$B$7<H16,"Not Started",IF(Control!$B$7>I16,"Late","Ready")))) -> Complete | V16: 46258 | W16: 46271
A17: B1.3 | B17: B | C17: Engineering Foundation | D17: B1 | E17: Development environment setup | F17: Document workstation setup and onboarding checks | G17: B1.2 | H17: 8 | I17: 8 | J17: 1 | K17: 1 | L17: Me | M17: Developer setup guide and onboarding checklist | N17: A clean workstation can reproduce the setup | P17: =IF(Control!$B$7<H17,0,IF(Control!$B$7>=I17,1,(Control!$B$7-H17+1)/J17)) -> 0 | Q17: 1 | R17: =K17/SUM($K$5:$K$137) -> 0.0054495913 | S17: =P17*R17 -> 0 | T17: =Q17*R17 -> 0.0054495913 | U17: =IF(Q17>=1,"Complete",IF(Q17>0,"In Progress",IF(Control!$B$7<H17,"Not Started",IF(Control!$B$7>I17,"Late","Ready")))) -> Complete | V17: 46265 | W17: 46271
A18: B2.1 | B18: B | C18: Engineering Foundation | D18: B2 | E18: Repository initialization | F18: Create production repository structure, .gitignore and component directories | G18: B1.2 | H18: 8 | I18: 8 | J18: 1 | K18: 1 | L18: Me | M18: Initialized repository and directory baseline | N18: Repository builds from a clean clone and generated files are excluded | P18: =IF(Control!$B$7<H18,0,IF(Control!$B$7>=I18,1,(Control!$B$7-H18+1)/J18)) -> 0 | Q18: 1 | R18: =K18/SUM($K$5:$K$137) -> 0.0054495913 | S18: =P18*R18 -> 0 | T18: =Q18*R18 -> 0.0054495913 | U18: =IF(Q18>=1,"Complete",IF(Q18>0,"In Progress",IF(Control!$B$7<H18,"Not Started",IF(Control!$B$7>I18,"Late","Ready")))) -> Complete | V18: 46265 | W18: 46271
A19: B2.2 | B19: B | C19: Engineering Foundation | D19: B2 | E19: Repository initialization | F19: Define branching, review, commit, release-tag and semantic-version policies | G19: B2.1 | H19: 9 | I19: 9 | J19: 1 | K19: 1 | L19: Me | M19: Source-control and versioning policy | N19: Release and change-control rules are explicit | P19: =IF(Control!$B$7<H19,0,IF(Control!$B$7>=I19,1,(Control!$B$7-H19+1)/J19)) -> 0 | Q19: 1 | R19: =K19/SUM($K$5:$K$137) -> 0.0054495913 | S19: =P19*R19 -> 0 | T19: =Q19*R19 -> 0.0054495913 | U19: =IF(Q19>=1,"Complete",IF(Q19>0,"In Progress",IF(Control!$B$7<H19,"Not Started",IF(Control!$B$7>I19,"Late","Ready")))) -> Complete | V19: 46272 | W19: 46278
A20: B2.3 | B20: B | C20: Engineering Foundation | D20: B2 | E20: Repository initialization | F20: Embed firmware metadata and verify secrets are excluded | G20: B2.2 | H20: 9 | I20: 9 | J20: 1 | K20: 1 | L20: Me | M20: Build metadata output and secret-scan evidence | N20: Binary identifies source/tool versions and no credentials are committed | P20: =IF(Control!$B$7<H20,0,IF(Control!$B$7>=I20,1,(Control!$B$7-H20+1)/J20)) -> 0 | Q20: 0 | R20: =K20/SUM($K$5:$K$137) -> 0.0054495913 | S20: =P20*R20 -> 0 | T20: =Q20*R20 -> 0 | U20: =IF(Q20>=1,"Complete",IF(Q20>0,"In Progress",IF(Control!$B$7<H20,"Not Started",IF(Control!$B$7>I20,"Late","Ready")))) -> Not Started | V20: 46272 | W20: 46278
A21: B3.1 | B21: B | C21: Engineering Foundation | D21: B3 | E21: Build configuration framework | F21: Create debug, validation and production sdkconfig profiles | G21: B2.3 | H21: 9 | I21: 10 | J21: 2 | K21: 2 | L21: Me | M21: Pinned sdkconfig defaults for all profiles | N21: All profiles build and documented differences match policy | P21: =IF(Control!$B$7<H21,0,IF(Control!$B$7>=I21,1,(Control!$B$7-H21+1)/J21)) -> 0 | Q21: 0 | R21: =K21/SUM($K$5:$K$137) -> 0.010899183 | S21: =P21*R21 -> 0 | T21: =Q21*R21 -> 0 | U21: =IF(Q21>=1,"Complete",IF(Q21>0,"In Progress",IF(Control!$B$7<H21,"Not Started",IF(Control!$B$7>I21,"Late","Ready")))) -> Not Started | V21: 46272 | W21: 46285
A22: B3.2 | B22: B | C22: Engineering Foundation | D22: B3 | E22: Build configuration framework | F22: Implement bootstrap, build, flash, erase, monitor and release scripts | G22: B3.1 | H22: 10 | I22: 11 | J22: 2 | K22: 2 | L22: Me | M22: PowerShell/Python build-tool scripts | N22: Scripts operate from a clean checkout without manual path edits | P22: =IF(Control!$B$7<H22,0,IF(Control!$B$7>=I22,1,(Control!$B$7-H22+1)/J22)) -> 0 | Q22: 0 | R22: =K22/SUM($K$5:$K$137) -> 0.010899183 | S22: =P22*R22 -> 0 | T22: =Q22*R22 -> 0 | U22: =IF(Q22>=1,"Complete",IF(Q22>0,"In Progress",IF(Control!$B$7<H22,"Not Started",IF(Control!$B$7>I22,"Late","Ready")))) -> Not Started | V22: 46279 | W22: 46292
A23: B3.3 | B23: B | C23: Engineering Foundation | D23: B3 | E23: Build configuration framework | F23: Add ESP-IDF version guard, image-size checks and deterministic build metadata | G23: B3.2 | H23: 11 | I23: 11 | J23: 1 | K23: 1 | L23: Me | M23: Version-check and image-budget reports | N23: Build fails on wrong toolchain or release-size violation | P23: =IF(Control!$B$7<H23,0,IF(Control!$B$7>=I23,1,(Control!$B$7-H23+1)/J23)) -> 0 | Q23: 0 | R23: =K23/SUM($K$5:$K$137) -> 0.0054495913 | S23: =P23*R23 -> 0 | T23: =Q23*R23 -> 0 | U23: =IF(Q23>=1,"Complete",IF(Q23>0,"In Progress",IF(Control!$B$7<H23,"Not Started",IF(Control!$B$7>I23,"Late","Ready")))) -> Not Started | V23: 46286 | W23: 46292
A24: B4.1 | B24: B | C24: Engineering Foundation | D24: B4 | E24: Continuous integration skeleton | F24: Create CI stages for format, static checks, host tests and profile builds | G24: B3.3 | H24: 11 | I24: 12 | J24: 2 | K24: 2 | L24: Me | M24: CI workflow and successful pipeline run | N24: Every change receives automated checks and build results | P24: =IF(Control!$B$7<H24,0,IF(Control!$B$7>=I24,1,(Control!$B$7-H24+1)/J24)) -> 0 | Q24: 0 | R24: =K24/SUM($K$5:$K$137) -> 0.010899183 | S24: =P24*R24 -> 0 | T24: =Q24*R24 -> 0 | U24: =IF(Q24>=1,"Complete",IF(Q24>0,"In Progress",IF(Control!$B$7<H24,"Not Started",IF(Control!$B$7>I24,"Late","Ready")))) -> Not Started | V24: 46286 | W24: 46299
A25: B4.2 | B25: B | C25: Engineering Foundation | D25: B4 | E25: Continuous integration skeleton | F25: Archive binaries, ELF, MAP, partition table, sdkconfig, logs and test reports | G25: B4.1 | H25: 12 | I25: 12 | J25: 1 | K25: 1 | L25: Me | M25: CI artifact archive | N25: Build outputs are traceable to source revision | P25: =IF(Control!$B$7<H25,0,IF(Control!$B$7>=I25,1,(Control!$B$7-H25+1)/J25)) -> 0 | Q25: 0 | R25: =K25/SUM($K$5:$K$137) -> 0.0054495913 | S25: =P25*R25 -> 0 | T25: =Q25*R25 -> 0 | U25: =IF(Q25>=1,"Complete",IF(Q25>0,"In Progress",IF(Control!$B$7<H25,"Not Started",IF(Control!$B$7>I25,"Late","Ready")))) -> Not Started | V25: 46293 | W25: 46299
A26: B4.3 | B26: B | C26: Engineering Foundation | D26: B4 | E26: Continuous integration skeleton | F26: Reproduce clean checkout-to-flash workflow and close Cluster B gate | G26: B1.3,B4.2 | H26: 12 | I26: 12 | J26: 1 | K26: 1.2 | L26: Me | M26: Engineering-baseline gate review | N26: Toolchain, repository, scripts and CI are reproducible | O26: G-B | P26: =IF(Control!$B$7<H26,0,IF(Control!$B$7>=I26,1,(Control!$B$7-H26+1)/J26)) -> 0 | Q26: 0 | R26: =K26/SUM($K$5:$K$137) -> 0.0065395095 | S26: =P26*R26 -> 0 | T26: =Q26*R26 -> 0 | U26: =IF(Q26>=1,"Complete",IF(Q26>0,"In Progress",IF(Control!$B$7<H26,"Not Started",IF(Control!$B$7>I26,"Late","Ready")))) -> Not Started | V26: 46293 | W26: 46299
A27: C1.1 | B27: C | C27: Platform and Architecture Development | D27: C1 | E27: System architecture | F27: Define firmware layers, component groups and dependency direction | G27: B4.3 | H27: 13 | I27: 13 | J27: 1 | K27: 1 | L27: Me | M27: Architecture document and component diagram | N27: Layering prevents product logic from bypassing platform abstractions | P27: =IF(Control!$B$7<H27,0,IF(Control!$B$7>=I27,1,(Control!$B$7-H27+1)/J27)) -> 0 | Q27: 0 | R27: =K27/SUM($K$5:$K$137) -> 0.0054495913 | S27: =P27*R27 -> 0 | T27: =Q27*R27 -> 0 | U27: =IF(Q27>=1,"Complete",IF(Q27>0,"In Progress",IF(Control!$B$7<H27,"Not Started",IF(Control!$B$7>I27,"Late","Ready")))) -> Not Started | V27: 46300 | W27: 46306
A28: C1.2 | B28: C | C28: Platform and Architecture Development | D28: C1 | E28: System architecture | F28: Specify component APIs, ownership, threading, initialization and error contracts | G28: C1.1 | H28: 13 | I28: 14 | J28: 2 | K28: 2 | L28: Me | M28: Component interface specifications | N28: Every mutable resource and interface has a single owner | P28: =IF(Control!$B$7<H28,0,IF(Control!$B$7>=I28,1,(Control!$B$7-H28+1)/J28)) -> 0 | Q28: 0 | R28: =K28/SUM($K$5:$K$137) -> 0.010899183 | S28: =P28*R28 -> 0 | T28: =Q28*R28 -> 0 | U28: =IF(Q28>=1,"Complete",IF(Q28>0,"In Progress",IF(Control!$B$7<H28,"Not Started",IF(Control!$B$7>I28,"Late","Ready")))) -> Not Started | V28: 46300 | W28: 46313
A29: C1.3 | B29: C | C29: Platform and Architecture Development | D29: C1 | E29: System architecture | F29: Record architecture decisions and review for circular/overlapping responsibilities | G29: C1.2 | H29: 14 | I29: 14 | J29: 1 | K29: 1 | L29: Me | M29: Architecture decision records and review checklist | N29: No circular dependencies or overlapping responsibilities remain | P29: =IF(Control!$B$7<H29,0,IF(Control!$B$7>=I29,1,(Control!$B$7-H29+1)/J29)) -> 0 | Q29: 0 | R29: =K29/SUM($K$5:$K$137) -> 0.0054495913 | S29: =P29*R29 -> 0 | T29: =Q29*R29 -> 0 | U29: =IF(Q29>=1,"Complete",IF(Q29>0,"In Progress",IF(Control!$B$7<H29,"Not Started",IF(Control!$B$7>I29,"Late","Ready")))) -> Not Started | V29: 46307 | W29: 46313
A30: C2.1 | B30: C | C30: Platform and Architecture Development | D30: C2 | E30: Board support package | F30: Define board pins, active levels, pulls, electrical capabilities and revision detection | G30: C1.3 | H30: 15 | I30: 15 | J30: 1 | K30: 1 | L30: Me | M30: Board pin map and revision strategy | N30: All board-specific data is isolated in the BSP | P30: =IF(Control!$B$7<H30,0,IF(Control!$B$7>=I30,1,(Control!$B$7-H30+1)/J30)) -> 0 | Q30: 0 | R30: =K30/SUM($K$5:$K$137) -> 0.0054495913 | S30: =P30*R30 -> 0 | T30: =Q30*R30 -> 0 | U30: =IF(Q30>=1,"Complete",IF(Q30>0,"In Progress",IF(Control!$B$7<H30,"Not Started",IF(Control!$B$7>I30,"Late","Ready")))) -> Not Started | V30: 46314 | W30: 46320
A31: C2.2 | B31: C | C31: Platform and Architecture Development | D31: C2 | E31: Board support package | F31: Implement safe startup, peripheral power sequencing and bus initialization | G31: C2.1 | H31: 15 | I31: 16 | J31: 2 | K31: 2 | L31: Me | M31: Board initialization code and startup-sequence trace | N31: Startup drives no unsafe outputs and buses initialize deterministically | P31: =IF(Control!$B$7<H31,0,IF(Control!$B$7>=I31,1,(Control!$B$7-H31+1)/J31)) -> 0 | Q31: 0 | R31: =K31/SUM($K$5:$K$137) -> 0.010899183 | S31: =P31*R31 -> 0 | T31: =Q31*R31 -> 0 | U31: =IF(Q31>=1,"Complete",IF(Q31>0,"In Progress",IF(Control!$B$7<H31,"Not Started",IF(Control!$B$7>I31,"Late","Ready")))) -> Not Started | V31: 46314 | W31: 46327
A32: C2.3 | B32: C | C32: Platform and Architecture Development | D32: C2 | E32: Board support package | F32: Build board self-test for GPIO, buttons, LED, I2C, SPI, OLED, SX1262, ADC and Vext | G32: C2.2 | H32: 16 | I32: 17 | J32: 2 | K32: 2 | L32: Me | M32: Board self-test application and pass report | N32: Every board peripheral is independently verified | P32: =IF(Control!$B$7<H32,0,IF(Control!$B$7>=I32,1,(Control!$B$7-H32+1)/J32)) -> 0 | Q32: 0 | R32: =K32/SUM($K$5:$K$137) -> 0.010899183 | S32: =P32*R32 -> 0 | T32: =Q32*R32 -> 0 | U32: =IF(Q32>=1,"Complete",IF(Q32>0,"In Progress",IF(Control!$B$7<H32,"Not Started",IF(Control!$B$7>I32,"Late","Ready")))) -> Not Started | V32: 46321 | W32: 46334
A33: C3.1 | B33: C | C33: Platform and Architecture Development | D33: C3 | E33: HAL and device drivers | F33: Implement HAL wrappers for GPIO, I2C, SPI, UART, ADC, PWM, timers and power | G33: C2.2 | H33: 18 | I33: 19 | J33: 2 | K33: 2 | L33: Me | M33: HAL components and API documentation | N33: Application and drivers use HAL contracts rather than raw peripheral calls | P33: =IF(Control!$B$7<H33,0,IF(Control!$B$7>=I33,1,(Control!$B$7-H33+1)/J33)) -> 0 | Q33: 0 | R33: =K33/SUM($K$5:$K$137) -> 0.010899183 | S33: =P33*R33 -> 0 | T33: =Q33*R33 -> 0 | U33: =IF(Q33>=1,"Complete",IF(Q33>0,"In Progress",IF(Control!$B$7<H33,"Not Started",IF(Control!$B$7>I33,"Late","Ready")))) -> Not Started | V33: 46335 | W33: 46348
A34: C3.2 | B34: C | C34: Platform and Architecture Development | D34: C3 | E34: HAL and device drivers | F34: Implement core sensor, actuator, LED and button drivers with structured errors | G34: C3.1 | H34: 19 | I34: 20 | J34: 2 | K34: 2 | L34: Me | M34: Core device-driver components and unit tests | N34: Normal, invalid-input, timeout and missing-device paths are covered | P34: =IF(Control!$B$7<H34,0,IF(Control!$B$7>=I34,1,(Control!$B$7-H34+1)/J34)) -> 0 | Q34: 0 | R34: =K34/SUM($K$5:$K$137) -> 0.010899183 | S34: =P34*R34 -> 0 | T34: =Q34*R34 -> 0 | U34: =IF(Q34>=1,"Complete",IF(Q34>0,"In Progress",IF(Control!$B$7<H34,"Not Started",IF(Control!$B$7>I34,"Late","Ready")))) -> Not Started | V34: 46342 | W34: 46355
A35: C3.3 | B35: C | C35: Platform and Architecture Development | D35: C3 | E35: HAL and device drivers | F35: Implement OLED, SX1262 and battery-monitor drivers | G35: C3.1,C2.3 | H35: 20 | I35: 21 | J35: 2 | K35: 2 | L35: Me | M35: Display, radio and battery driver test applications | N35: Drivers initialize and recover from communication faults | P35: =IF(Control!$B$7<H35,0,IF(Control!$B$7>=I35,1,(Control!$B$7-H35+1)/J35)) -> 0 | Q35: 0 | R35: =K35/SUM($K$5:$K$137) -> 0.010899183 | S35: =P35*R35 -> 0 | T35: =Q35*R35 -> 0 | U35: =IF(Q35>=1,"Complete",IF(Q35>0,"In Progress",IF(Control!$B$7<H35,"Not Started",IF(Control!$B$7>I35,"Late","Ready")))) -> Not Started | V35: 46349 | W35: 46362
A36: C3.4 | B36: C | C36: Platform and Architecture Development | D36: C3 | E36: HAL and device drivers | F36: Run bus recovery, repeated-init and ownership/concurrency tests | G36: C3.2,C3.3 | H36: 21 | I36: 21 | J36: 1 | K36: 1 | L36: Me | M36: Driver fault-injection report | N36: Peripheral access is serialized and structured errors propagate | P36: =IF(Control!$B$7<H36,0,IF(Control!$B$7>=I36,1,(Control!$B$7-H36+1)/J36)) -> 0 | Q36: 0 | R36: =K36/SUM($K$5:$K$137) -> 0.0054495913 | S36: =P36*R36 -> 0 | T36: =Q36*R36 -> 0 | U36: =IF(Q36>=1,"Complete",IF(Q36>0,"In Progress",IF(Control!$B$7<H36,"Not Started",IF(Control!$B$7>I36,"Late","Ready")))) -> Not Started | V36: 46356 | W36: 46362
A37: C4.1 | B37: C | C37: Platform and Architecture Development | D37: C4 | E37: Flash, bootloader, and partition architecture | F37: Design 8 MB partition table and warning/release/hard image budgets | G37: C1.3 | H37: 15 | I37: 16 | J37: 2 | K37: 2 | L37: Me | M37: Production partition CSV and size-budget rationale | N37: All partitions fit and both OTA slots accept the release limit | P37: =IF(Control!$B$7<H37,0,IF(Control!$B$7>=I37,1,(Control!$B$7-H37+1)/J37)) -> 0 | Q37: 0 | R37: =K37/SUM($K$5:$K$137) -> 0.010899183 | S37: =P37*R37 -> 0 | T37: =Q37*R37 -> 0 | U37: =IF(Q37>=1,"Complete",IF(Q37>0,"In Progress",IF(Control!$B$7<H37,"Not Started",IF(Control!$B$7>I37,"Late","Ready")))) -> Not Started | V37: 46314 | W37: 46327
A38: C4.2 | B38: C | C38: Platform and Architecture Development | D38: C4 | E38: Flash, bootloader, and partition architecture | F38: Define boot selection, trial-boot, rollback and recovery-entry flows | G38: C4.1 | H38: 17 | I38: 17 | J38: 1 | K38: 1 | L38: Me | M38: Boot-flow and recovery-flow diagrams | N38: All boot and recovery paths have deterministic entry criteria | P38: =IF(Control!$B$7<H38,0,IF(Control!$B$7>=I38,1,(Control!$B$7-H38+1)/J38)) -> 0 | Q38: 0 | R38: =K38/SUM($K$5:$K$137) -> 0.0054495913 | S38: =P38*R38 -> 0 | T38: =Q38*R38 -> 0 | U38: =IF(Q38>=1,"Complete",IF(Q38>0,"In Progress",IF(Control!$B$7<H38,"Not Started",IF(Control!$B$7>I38,"Late","Ready")))) -> Not Started | V38: 46328 | W38: 46334
... A56: C8.4 | B56: C | C56: Platform and Architecture Development | D56: C8 | E56: Diagnostics and health monitoring | F56: Document core-dump retrieval and diagnostic triage workflow | G56: C8.3 | H56: 31 | I56: 31 | J56: 1 | K56: 1 | L56: Me | M56: Field diagnostic and core-dump guide | N56: A fault can be captured, decoded and linked to a build | P56: =IF(Control!$B$7<H56,0,IF(Control!$B$7>=I56,1,(Control!$B$7-H56+1)/J56)) -> 0 | Q56: 0 | R56: =K56/SUM($K$5:$K$137) -> 0.0054495913 | S56: =P56*R56 -> 0 | T56: =Q56*R56 -> 0 | U56: =IF(Q56>=1,"Complete",IF(Q56>0,"In Progress",IF(Control!$B$7<H56,"Not Started",IF(Control!$B$7>I56,"Late","Ready")))) -> Not Started | V56: 46426 | W56: 46432
A57: C.G1 | B57: C | C57: Platform and Architecture Development | D57: C8 | E57: Diagnostics and health monitoring | F57: Integrate board, drivers, storage, startup, RTOS and diagnostics into platform baseline | G57: C5.4,C6.4,C7.4,C8.4 | H57: 32 | I57: 33 | J57: 2 | K57: 2.6 | L57: Me | M57: Integrated platform build and interface test report | N57: Platform services run together without product-specific coupling | O57: G-C | P57: =IF(Control!$B$7<H57,0,IF(Control!$B$7>=I57,1,(Control!$B$7-H57+1)/J57)) -> 0 | Q57: 0 | R57: =K57/SUM($K$5:$K$137) -> 0.014168937 | S57: =P57*R57 -> 0 | T57: =Q57*R57 -> 0 | U57: =IF(Q57>=1,"Complete",IF(Q57>0,"In Progress",IF(Control!$B$7<H57,"Not Started",IF(Control!$B$7>I57,"Late","Ready")))) -> Not Started | V57: 46433 | W57: 46446
A58: C.G2 | B58: C | C58: Platform and Architecture Development | D58: C8 | E58: Diagnostics and health monitoring | F58: Run 72-hour platform soak, close blockers and approve Cluster C gate | G58: C.G1 | H58: 33 | I58: 34 | J58: 2 | K58: 2.6 | L58: Me | M58: Soak report, defect closure list and platform-baseline approval | N58: No unexplained reset, heap drift or critical open defect remains | O58: G-C | P58: =IF(Control!$B$7<H58,0,IF(Control!$B$7>=I58,1,(Control!$B$7-H58+1)/J58)) -> 0 | Q58: 0 | R58: =K58/SUM($K$5:$K$137) -> 0.014168937 | S58: =P58*R58 -> 0 | T58: =Q58*R58 -> 0 | U58: =IF(Q58>=1,"Complete",IF(Q58>0,"In Progress",IF(Control!$B$7<H58,"Not Started",IF(Control!$B$7>I58,"Late","Ready")))) -> Not Started | V58: 46440 | W58: 46453
...

Sheet Phase Summary
A1: Phase-Level Summary
A3: Phase | B3: Cluster | C3: Phase Name | D3: Start Week | E3: End Week | F3: Owner | G3: Planned % | H3: Actual % | I3: Variance | J3: Work Packages | K3: Complete | L3: Phase Status
A4: A1 | B4: A | C4: Product concept definition | D4: 1 | E4: 2 | F4: Me | G4: =IFERROR(SUMIF(WBS!$D$5:$D$137,A4,WBS!$S$5:$S$137)/SUMIF(WBS!$D$5:$D$137,A4,WBS!$R$5:$R$137),0) -> 0.5 | H4: =IFERROR(SUMIF(WBS!$D$5:$D$137,A4,WBS!$T$5:$T$137)/SUMIF(WBS!$D$5:$D$137,A4,WBS!$R$5:$R$137),0) -> 1 | I4: =H4-G4 -> 0.5 | J4: 3 | K4: =COUNTIFS(WBS!$D$5:$D$137,A4,WBS!$U$5:$U$137,"Complete") -> 3 | L4: =IF(H4>=1,"Complete",IF(H4>0,"In Progress",IF(Control!$B$7<D4,"Not Started",IF(Control!$B$7>E4,"Late","Ready")))) -> Complete
A5: A2 | B5: A | C5: Requirements engineering | D5: 2 | E5: 4 | F5: Me | G5: =IFERROR(SUMIF(WBS!$D$5:$D$137,A5,WBS!$S$5:$S$137)/SUMIF(WBS!$D$5:$D$137,A5,WBS!$R$5:$R$137),0) -> 0 | H5: =IFERROR(SUMIF(WBS!$D$5:$D$137,A5,WBS!$T$5:$T$137)/SUMIF(WBS!$D$5:$D$137,A5,WBS!$R$5:$R$137),0) -> 1 | I5: =H5-G5 -> 1 | J5: 4 | K5: =COUNTIFS(WBS!$D$5:$D$137,A5,WBS!$U$5:$U$137,"Complete") -> 4 | L5: =IF(H5>=1,"Complete",IF(H5>0,"In Progress",IF(Control!$B$7<D5,"Not Started",IF(Control!$B$7>E5,"Late","Ready")))) -> Complete
A6: A3 | B6: A | C6: Feasibility and risk analysis | D6: 4 | E6: 6 | F6: Me | G6: =IFERROR(SUMIF(WBS!$D$5:$D$137,A6,WBS!$S$5:$S$137)/SUMIF(WBS!$D$5:$D$137,A6,WBS!$R$5:$R$137),0) -> 0 | H6: =IFERROR(SUMIF(WBS!$D$5:$D$137,A6,WBS!$T$5:$T$137)/SUMIF(WBS!$D$5:$D$137,A6,WBS!$R$5:$R$137),0) -> 1 | I6: =H6-G6 -> 1 | J6: 3 | K6: =COUNTIFS(WBS!$D$5:$D$137,A6,WBS!$U$5:$U$137,"Complete") -> 3 | L6: =IF(H6>=1,"Complete",IF(H6>0,"In Progress",IF(Control!$B$7<D6,"Not Started",IF(Control!$B$7>E6,"Late","Ready")))) -> Complete
A7: B1 | B7: B | C7: Development environment setup | D7: 7 | E7: 8 | F7: Me | G7: =IFERROR(SUMIF(WBS!$D$5:$D$137,A7,WBS!$S$5:$S$137)/SUMIF(WBS!$D$5:$D$137,A7,WBS!$R$5:$R$137),0) -> 0 | H7: =IFERROR(SUMIF(WBS!$D$5:$D$137,A7,WBS!$T$5:$T$137)/SUMIF(WBS!$D$5:$D$137,A7,WBS!$R$5:$R$137),0) -> 1 | I7: =H7-G7 -> 1 | J7: 3 | K7: =COUNTIFS(WBS!$D$5:$D$137,A7,WBS!$U$5:$U$137,"Complete") -> 3 | L7: =IF(H7>=1,"Complete",IF(H7>0,"In Progress",IF(Control!$B$7<D7,"Not Started",IF(Control!$B$7>E7,"Late","Ready")))) -> Complete
A8: B2 | B8: B | C8: Repository initialization | D8: 8 | E8: 9 | F8: Me | G8: =IFERROR(SUMIF(WBS!$D$5:$D$137,A8,WBS!$S$5:$S$137)/SUMIF(WBS!$D$5:$D$137,A8,WBS!$R$5:$R$137),0) -> 0 | H8: =IFERROR(SUMIF(WBS!$D$5:$D$137,A8,WBS!$T$5:$T$137)/SUMIF(WBS!$D$5:$D$137,A8,WBS!$R$5:$R$137),0) -> 0.66666667 | I8: =H8-G8 -> 0.66666667 | J8: 3 | K8: =COUNTIFS(WBS!$D$5:$D$137,A8,WBS!$U$5:$U$137,"Complete") -> 2 | L8: =IF(H8>=1,"Complete",IF(H8>0,"In Progress",IF(Control!$B$7<D8,"Not Started",IF(Control!$B$7>E8,"Late","Ready")))) -> In Progress
A9: B3 | B9: B | C9: Build configuration framework | D9: 9 | E9: 11 | F9: Me | G9: =IFERROR(SUMIF(WBS!$D$5:$D$137,A9,WBS!$S$5:$S$137)/SUMIF(WBS!$D$5:$D$137,A9,WBS!$R$5:$R$137),0) -> 0 | H9: =IFERROR(SUMIF(WBS!$D$5:$D$137,A9,WBS!$T$5:$T$137)/SUMIF(WBS!$D$5:$D$137,A9,WBS!$R$5:$R$137),0) -> 0 | I9: =H9-G9 -> 0 | J9: 3 | K9: =COUNTIFS(WBS!$D$5:$D$137,A9,WBS!$U$5:$U$137,"Complete") -> 0 | L9: =IF(H9>=1,"Complete",IF(H9>0,"In Progress",IF(Control!$B$7<D9,"Not Started",IF(Control!$B$7>E9,"Late","Ready")))) -> Not Started
A10: B4 | B10: B | C10: Continuous integration skeleton | D10: 11 | E10: 12 | F10: Me | G10: =IFERROR(SUMIF(WBS!$D$5:$D$137,A10,WBS!$S$5:$S$137)/SUMIF(WBS!$D$5:$D$137,A10,WBS!$R$5:$R$137),0) -> 0 | H10: =IFERROR(SUMIF(WBS!$D$5:$D$137,A10,WBS!$T$5:$T$137)/SUMIF(WBS!$D$5:$D$137,A10,WBS!$R$5:$R$137),0) -> 0 | I10: =H10-G10 -> 0 | J10: 3 | K10: =COUNTIFS(WBS!$D$5:$D$137,A10,WBS!$U$5:$U$137,"Complete") -> 0 | L10: =IF(H10>=1,"Complete",IF(H10>0,"In Progress",IF(Control!$B$7<D10,"Not Started",IF(Control!$B$7>E10,"Late","Ready")))) -> Not Started
A11: C1 | B11: C | C11: System architecture | D11: 13 | E11: 14 | F11: Me | G11: =IFERROR(SUMIF(WBS!$D$5:$D$137,A11,WBS!$S$5:$S$137)/SUMIF(WBS!$D$5:$D$137,A11,WBS!$R$5:$R$137),0) -> 0 | H11: =IFERROR(SUMIF(WBS!$D$5:$D$137,A11,WBS!$T$5:$T$137)/SUMIF(WBS!$D$5:$D$137,A11,WBS!$R$5:$R$137),0) -> 0 | I11: =H11-G11 -> 0 | J11: 3 | K11: =COUNTIFS(WBS!$D$5:$D$137,A11,WBS!$U$5:$U$137,"Complete") -> 0 | L11: =IF(H11>=1,"Complete",IF(H11>0,"In Progress",IF(Control!$B$7<D11,"Not Started",IF(Control!$B$7>E11,"Late","Ready")))) -> Not Started
A12: C2 | B12: C | C12: Board support package | D12: 15 | E12: 17 | F12: Me | G12: =IFERROR(SUMIF(WBS!$D$5:$D$137,A12,WBS!$S$5:$S$137)/SUMIF(WBS!$D$5:$D$137,A12,WBS!$R$5:$R$137),0) -> 0 | H12: =IFERROR(SUMIF(WBS!$D$5:$D$137,A12,WBS!$T$5:$T$137)/SUMIF(WBS!$D$5:$D$137,A12,WBS!$R$5:$R$137),0) -> 0 | I12: =H12-G12 -> 0 | J12: 3 | K12: =COUNTIFS(WBS!$D$5:$D$137,A12,WBS!$U$5:$U$137,"Complete") -> 0 | L12: =IF(H12>=1,"Complete",IF(H12>0,"In Progress",IF(Control!$B$7<D12,"Not Started",IF(Control!$B$7>E12,"Late","Ready")))) -> Not Started
A13: C3 | B13: C | C13: HAL and device drivers | D13: 18 | E13: 21 | F13: Me | G13: =IFERROR(SUMIF(WBS!$D$5:$D$137,A13,WBS!$S$5:$S$137)/SUMIF(WBS!$D$5:$D$137,A13,WBS!$R$5:$R$137),0) -> 0 | H13: =IFERROR(SUMIF(WBS!$D$5:$D$137,A13,WBS!$T$5:$T$137)/SUMIF(WBS!$D$5:$D$137,A13,WBS!$R$5:$R$137),0) -> 0 | I13: =H13-G13 -> 0 | J13: 4 | K13: =COUNTIFS(WBS!$D$5:$D$137,A13,WBS!$U$5:$U$137,"Complete") -> 0 | L13: =IF(H13>=1,"Complete",IF(H13>0,"In Progress",IF(Control!$B$7<D13,"Not Started",IF(Control!$B$7>E13,"Late","Ready")))) -> Not Started
A14: C4 | B14: C | C14: Flash, bootloader, and partition architecture | D14: 15 | E14: 18 | F14: Me | G14: =IFERROR(SUMIF(WBS!$D$5:$D$137,A14,WBS!$S$5:$S$137)/SUMIF(WBS!$D$5:$D$137,A14,WBS!$R$5:$R$137),0) -> 0 | H14: =IFERROR(SUMIF(WBS!$D$5:$D$137,A14,WBS!$T$5:$T$137)/SUMIF(WBS!$D$5:$D$137,A14,WBS!$R$5:$R$137),0) -> 0 | I14: =H14-G14 -> 0 | J14: 4 | K14: =COUNTIFS(WBS!$D$5:$D$137,A14,WBS!$U$5:$U$137,"Complete") -> 0 | L14: =IF(H14>=1,"Complete",IF(H14>0,"In Progress",IF(Control!$B$7<D14,"Not Started",IF(Control!$B$7>E14,"Late","Ready")))) -> Not Started
A15: C5 | B15: C | C15: Startup and service supervision | D15: 22 | E15: 24 | F15: Me | G15: =IFERROR(SUMIF(WBS!$D$5:$D$137,A15,WBS!$S$5:$S$137)/SUMIF(WBS!$D$5:$D$137,A15,WBS!$R$5:$R$137),0) -> 0 | H15: =IFERROR(SUMIF(WBS!$D$5:$D$137,A15,WBS!$T$5:$T$137)/SUMIF(WBS!$D$5:$D$137,A15,WBS!$R$5:$R$137),0) -> 0 | I15: =H15-G15 -> 0 | J15: 4 | K15: =COUNTIFS(WBS!$D$5:$D$137,A15,WBS!$U$5:$U$137,"Complete") -> 0 | L15: =IF(H15>=1,"Complete",IF(H15>0,"In Progress",IF(Control!$B$7<D15,"Not Started",IF(Control!$B$7>E15,"Late","Ready")))) -> Not Started
... A43: G6 | B43: G | C43: End-of-life | D43: 89 | E43: 90 | F43: Me | G43: =IFERROR(SUMIF(WBS!$D$5:$D$137,A43,WBS!$S$5:$S$137)/SUMIF(WBS!$D$5:$D$137,A43,WBS!$R$5:$R$137),0) -> 0 | H43: =IFERROR(SUMIF(WBS!$D$5:$D$137,A43,WBS!$T$5:$T$137)/SUMIF(WBS!$D$5:$D$137,A43,WBS!$R$5:$R$137),0) -> 0 | I43: =H43-G43 -> 0 | J43: 2 | K43: =COUNTIFS(WBS!$D$5:$D$137,A43,WBS!$U$5:$U$137,"Complete") -> 0 | L43: =IF(H43>=1,"Complete",IF(H43>0,"In Progress",IF(Control!$B$7<D43,"Not Started",IF(Control!$B$7>E43,"Late","Ready")))) -> Not Started

Sheet Weekly Plan
A1: 90-Week Solo Execution Plan
A3: Week | B3: Week Start | C3: Week Finish | D3: Active WBS IDs | E3: Weekly Focus | F3: Evidence Due | G3: Gate / Milestone | H3: Planned Cumulative % | I3: Actual Snapshot
A4: 1 | B4: 46216 | C4: 46222 | D4: A1.1, A1.2 | E4: A1.1: Define users, operating environment, installation, power, connectivity, UI, maintenance and update strategy A1.2: Model normal and abnormal operating scenarios | F4: A1.1: Product concept document and primary use-case list | H4: 0.010899183 | I4: =IF(A4=Control!$B$7,Control!$B$11,"") -> 0.11553134
A5: 2 | B5: 46223 | C5: 46229 | D5: A1.2, A1.3, A2.1 | E5: A1.2: Model normal and abnormal operating scenarios A1.3: Define firmware, cloud, mobile, factory and recovery boundaries A2.1: Write uniquely identified functional requirements | F5: A1.2: Normal/abnormal scenario catalogue A1.3: System context diagram and product-boundary document | H5: 0.027247956 | I5: =IF(A5=Control!$B$7,Control!$B$11,"")
A6: 3 | B6: 46230 | C6: 46236 | D6: A2.1, A2.2, A2.3 | E6: A2.1: Write uniquely identified functional requirements A2.2: Set measurable non-functional budgets for timing, memory, power, availability and security A2.3: Define hardware, communications, diagnostics, manufacturing and OTA interfaces plus environmental constraints | F6: A2.1: System requirements specification with FR identifiers A2.2: Non-functional requirements specification | H6: 0.04359673 | I6: =IF(A6=Control!$B$7,Control!$B$11,"")
A7: 4 | B7: 46237 | C7: 46243 | D7: A2.3, A2.4, A3.1 | E7: A2.3: Define hardware, communications, diagnostics, manufacturing and OTA interfaces plus environmental constraints A2.4: Build requirements traceability matrix and initial acceptance-test list A3.1: Validate ESP32-S3/Heltec V3 hardware constraints, pins, flash, PSRAM, RF, USB and power controls | F7: A2.3: Interface control document and environmental/regulatory checklist A2.4: Requirements traceability matrix and acceptance-test catalogue | H7: 0.059945504 | I7: =IF(A7=Control!$B$7,Control!$B$11,"")
A8: 5 | B8: 46244 | C8: 46250 | D8: A3.1, A3.2 | E8: A3.1: Validate ESP32-S3/Heltec V3 hardware constraints, pins, flash, PSRAM, RF, USB and power controls A3.2: Prototype high-risk software capabilities: provisioning, LoRaWAN, TLS, OTA, sleep and storage recovery | F8: A3.1: Hardware feasibility report and verified pin/constraint list | H8: 0.070844687 | I8: =IF(A8=Control!$B$7,Control!$B$11,"")
A9: 6 | B9: 46251 | C9: 46257 | D9: A3.2, A3.3 | E9: A3.2: Prototype high-risk software capabilities: provisioning, LoRaWAN, TLS, OTA, sleep and storage recovery A3.3: Create risk register and preliminary threat model; close Cluster A gate | F9: A3.2: Proof-of-concept applications and test logs A3.3: Risk register, threat model and requirements-baseline review record | G9: G-A: Risks have mitigations and the requirements baseline is accepted | H9: 0.082833787 | I9: =IF(A9=Control!$B$7,Control!$B$11,"")
A10: 7 | B10: 46258 | C10: 46264 | D10: B1.1, B1.2 | E10: B1.1: Install and pin VS Code, ESP-IDF, Git, Python, CMake/Ninja, drivers and debugger support B1.2: Build, flash and monitor a minimal ESP32-S3 project from the controlled workspace | F10: B1.1: Tool-version manifest and installation record | H10: 0.09373297 | I10: =IF(A10=Control!$B$7,Control!$B$11,"")
A11: 8 | B11: 46265 | C11: 46271 | D11: B1.2, B1.3, B2.1 | E11: B1.2: Build, flash and monitor a minimal ESP32-S3 project from the controlled workspace B1.3: Document workstation setup and onboarding checks B2.1: Create production repository structure, .gitignore and component directories | F11: B1.2: Minimal project binary, flash log and serial monitor capture B1.3: Developer setup guide and onboarding checklist B2.1: Initialized repository and directory baseline | H11: 0.11008174 | I11: =IF(A11=Control!$B$7,Control!$B$11,"")
A12: 9 | B12: 46272 | C12: 46278 | D12: B2.2, B2.3, B3.1 | E12: B2.2: Define branching, review, commit, release-tag and semantic-version policies B2.3: Embed firmware metadata and verify secrets are excluded B3.1: Create debug, validation and production sdkconfig profiles | F12: B2.2: Source-control and versioning policy B2.3: Build metadata output and secret-scan evidence | H12: 0.12643052 | I12: =IF(A12=Control!$B$7,Control!$B$11,"")
A13: 10 | B13: 46279 | C13: 46285 | D13: B3.1, B3.2 | E13: B3.1: Create debug, validation and production sdkconfig profiles B3.2: Implement bootstrap, build, flash, erase, monitor and release scripts | F13: B3.1: Pinned sdkconfig defaults for all profiles | H13: 0.1373297 | I13: =IF(A13=Control!$B$7,Control!$B$11,"")
A14: 11 | B14: 46286 | C14: 46292 | D14: B3.2, B3.3, B4.1 | E14: B3.2: Implement bootstrap, build, flash, erase, monitor and release scripts B3.3: Add ESP-IDF version guard, image-size checks and deterministic build metadata B4.1: Create CI stages for format, static checks, host tests and profile builds | F14: B3.2: PowerShell/Python build-tool scripts B3.3: Version-check and image-budget reports | H14: 0.15367847 | I14: =IF(A14=Control!$B$7,Control!$B$11,"")
A15: 12 | B15: 46293 | C15: 46299 | D15: B4.1, B4.2, B4.3 | E15: B4.1: Create CI stages for format, static checks, host tests and profile builds B4.2: Archive binaries, ELF, MAP, partition table, sdkconfig, logs and test reports B4.3: Reproduce clean checkout-to-flash workflow and close Cluster B gate | F15: B4.1: CI workflow and successful pipeline run B4.2: CI artifact archive B4.3: Engineering-baseline gate review | G15: G-B: Toolchain, repository, scripts and CI are reproducible | H15: 0.17111717 | I15: =IF(A15=Control!$B$7,Control!$B$11,"")
A16: 13 | B16: 46300 | C16: 46306 | D16: C1.1, C1.2 | E16: C1.1: Define firmware layers, component groups and dependency direction C1.2: Specify component APIs, ownership, threading, initialization and error contracts | F16: C1.1: Architecture document and component diagram | H16: 0.18201635 | I16: =IF(A16=Control!$B$7,Control!$B$11,"")
A17: 14 | B17: 46307 | C17: 46313 | D17: C1.2, C1.3 | E17: C1.2: Specify component APIs, ownership, threading, initialization and error contracts C1.3: Record architecture decisions and review for circular/overlapping responsibilities | F17: C1.2: Component interface specifications C1.3: Architecture decision records and review checklist | H17: 0.19291553 | I17: =IF(A17=Control!$B$7,Control!$B$11,"")
A18: 15 | B18: 46314 | C18: 46320 | D18: C2.1, C2.2, C4.1 | E18: C2.1: Define board pins, active levels, pulls, electrical capabilities and revision detection C2.2: Implement safe startup, peripheral power sequencing and bus initialization C4.1: Design 8 MB partition table and warning/release/hard image budgets | F18: C2.1: Board pin map and revision strategy | H18: 0.20926431 | I18: =IF(A18=Control!$B$7,Control!$B$11,"")
A19: 16 | B19: 46321 | C19: 46327 | D19: C2.2, C2.3, C4.1 | E19: C2.2: Implement safe startup, peripheral power sequencing and bus initialization C2.3: Build board self-test for GPIO, buttons, LED, I2C, SPI, OLED, SX1262, ADC and Vext C4.1: Design 8 MB partition table and warning/release/hard image budgets | F19: C2.2: Board initialization code and startup-sequence trace C4.1: Production partition CSV and size-budget rationale | H19: 0.22561308 | I19: =IF(A19=Control!$B$7,Control!$B$11,"")
A20: 17 | B20: 46328 | C20: 46334 | D20: C2.3, C4.2 | E20: C2.3: Build board self-test for GPIO, buttons, LED, I2C, SPI, OLED, SX1262, ADC and Vext C4.2: Define boot selection, trial-boot, rollback and recovery-entry flows | F20: C2.3: Board self-test application and pass report C4.2: Boot-flow and recovery-flow diagrams | H20: 0.23651226 | I20: =IF(A20=Control!$B$7,Control!$B$11,"")
A21: 18 | B21: 46335 | C21: 46341 | D21: C3.1, C4.3, C4.4 | E21: C3.1: Implement HAL wrappers for GPIO, I2C, SPI, UART, ADC, PWM, timers and power C4.3: Implement recovery application skeleton and partition inspection C4.4: Validate partition offsets, maximum images and migration constraints | F21: C4.3: Bootable recovery image C4.4: Partition validation report | H21: 0.25286104 | I21: =IF(A21=Control!$B$7,Control!$B$11,"")
A22: 19 | B22: 46342 | C22: 46348 | D22: C3.1, C3.2 | E22: C3.1: Implement HAL wrappers for GPIO, I2C, SPI, UART, ADC, PWM, timers and power C3.2: Implement core sensor, actuator, LED and button drivers with structured errors | F22: C3.1: HAL components and API documentation | H22: 0.26376022 | I22: =IF(A22=Control!$B$7,Control!$B$11,"")
A23: 20 | B23: 46349 | C23: 46355 | D23: C3.2, C3.3 | E23: C3.2: Implement core sensor, actuator, LED and button drivers with structured errors C3.3: Implement OLED, SX1262 and battery-monitor drivers | F23: C3.2: Core device-driver components and unit tests | H23: 0.2746594 | I23: =IF(A23=Control!$B$7,Control!$B$11,"")
A24: 21 | B24: 46356 | C24: 46362 | D24: C3.3, C3.4 | E24: C3.3: Implement OLED, SX1262 and battery-monitor drivers C3.4: Run bus recovery, repeated-init and ownership/concurrency tests | F24: C3.3: Display, radio and battery driver test applications C3.4: Driver fault-injection report | H24: 0.28555858 | I24: =IF(A24=Control!$B$7,Control!$B$11,"")
A25: 22 | B25: 46363 | C25: 46369 | D25: C5.1, C5.2, C6.1 | E25: C5.1: Implement early startup, reset capture, NVS/config/identity load and board initialization C5.2: Implement startup state machine and service result model C6.1: Define RTOS task ownership, priorities, stack budgets and liveness conditions | F25: C5.1: Minimal app_main and early-startup trace C6.1: Task architecture and priority/stack table | H25: 0.30190736 | I25: =IF(A25=Control!$B$7,Control!$B$11,"")
A26: 23 | B26: 46370 | C26: 46376 | D26: C5.2, C5.3, C6.2 | E26: C5.2: Implement startup state machine and service result model C5.3: Implement boot-loop persistence, safe mode and recovery escalation C6.2: Implement typed commands/events, bounded queues, notifications and timers | F26: C5.2: Startup coordinator and supervisor | H26: 0.31825613 | I26: =IF(A26=Control!$B$7,Control!$B$11,"")
A27: 24 | B27: 46377 | C27: 46383 | D27: C5.3, C5.4, C6.2, C6.3 | E27: C5.3: Implement boot-loop persistence, safe mode and recovery escalation C5.4: Test normal, degraded, fatal and recovery startup paths C6.2: Implement typed commands/events, bounded queues, notifications and timers C6.3: Configure stack monitoring, watchdog participation and blocking-time limits | F27: C5.3: Boot-failure policy and safe-mode implementation C5.4: Startup-path test report C6.2: Queue/event catalogue and messaging framework | H27: 0.3400545 | I27: =IF(A27=Control!$B$7,Control!$B$11,"")
... A34: 31 | B34: 46426 | C34: 46432 | D34: C8.3, C8.4 | E34: C8.3: Enable watchdog layers, core-dump partition and pre-crash event buffer C8.4: Document core-dump retrieval and diagnostic triage workflow | F34: C8.3: Watchdog/core-dump configuration and captured sample fault C8.4: Field diagnostic and core-dump guide | H34: 0.41634877 | I34: =IF(A34=Control!$B$7,Control!$B$11,"")
A35: 32 | B35: 46433 | C35: 46439 | D35: C.G1 | E35: C.G1: Integrate board, drivers, storage, startup, RTOS and diagnostics into platform baseline | H35: 0.42343324 | I35: =IF(A35=Control!$B$7,Control!$B$11,"")
A36: 33 | B36: 46440 | C36: 46446 | D36: C.G1, C.G2 | E36: C.G1: Integrate board, drivers, storage, startup, RTOS and diagnostics into platform baseline C.G2: Run 72-hour platform soak, close blockers and approve Cluster C gate | F36: C.G1: Integrated platform build and interface test report | G36: G-C: Platform services run together without product-specific coupling | H36: 0.43760218 | I36: =IF(A36=Control!$B$7,Control!$B$11,"")
A37: 34 | B37: 46447 | C37: 46453 | D37: C.G2 | E37: C.G2: Run 72-hour platform soak, close blockers and approve Cluster C gate | F37: C.G2: Soak report, defect closure list and platform-baseline approval | G37: G-C: No unexplained reset, heap drift or critical open defect remains | H37: 0.44468665 | I37: =IF(A37=Control!$B$7,Control!$B$11,"")
A38: 35 | B38: 46454 | C38: 46460 | D38: D1.1, D8.1 | E38: D1.1: Define device states, product commands and events D8.1: Finalize security architecture, assets, trust boundaries and attack surfaces | F38: D1.1: Product state diagram and command/event catalogue | H38: 0.45558583 | I38: =IF(A38=Control!$B$7,Control!$B$11,"")
A39: 36 | B39: 46461 | C39: 46467 | D39: D1.2, D8.1 | E39: D1.2: Implement transition handlers, timeouts, failure paths and persistent state D8.1: Finalize security architecture, assets, trust boundaries and attack surfaces | F39: D1.2: State transition table and implementation D8.1: Updated threat model and security architecture | H39: 0.46648501 | I39: =IF(A39=Control!$B$7,Control!$B$11,"")
A40: 37 | B40: 46468 | C40: 46474 | D40: D1.3 | E40: D1.3: Unit-test normal, degraded, maintenance, update, safe and recovery transitions | F40: D1.3: State-machine unit-test report | H40: 0.4719346 | I40: =IF(A40=Control!$B$7,Control!$B$11,"")
A41: 38 | B41: 46475 | C41: 46481 | D41: D2.1, D5.1 | E41: D2.1: Implement single-owner Wi-Fi network manager and lifecycle states D5.1: Implement acquisition validation, calibration, normalization and filtering pipeline | F41: D2.1: Network manager component | H41: 0.48283379 | I41: =IF(A41=Control!$B$7,Control!$B$11,"")
A42: 39 | B42: 46482 | C42: 46488 | D42: D2.2, D5.1, D5.2 | E42: D2.2: Implement selected provisioning and authorized reset workflow D5.1: Implement acquisition validation, calibration, normalization and filtering pipeline D5.2: Implement control rules, hysteresis, timing, safety limits and manual override | F42: D2.2: Provisioning service and provisioning test logs D5.1: Acquisition service and sample-quality tests | H42: 0.49918256 | I42: =IF(A42=Control!$B$7,Control!$B$11,"")
A43: 40 | B43: 46489 | C43: 46495 | D43: D2.3, D2.4, D5.2 | E43: D2.3: Implement exponential backoff with jitter and connection diagnostics D2.4: Test long-duration network loss, recovery and repeated provisioning D5.2: Implement control rules, hysteresis, timing, safety limits and manual override | F43: D2.3: Retry/backoff implementation and metrics D2.4: Connectivity resilience report D5.2: Control service and rule-test report | H43: 0.51553134 | I43: =IF(A43=Control!$B$7,Control!$B$11,"")
A44: 41 | B44: 46496 | C44: 46502 | D44: D3.1, D5.3 | E44: D3.1: Integrate SX1262 reset, busy, DIO, frequency, power, sleep and wake behavior D5.3: Implement calibration storage, validity, migration and corrupt-data fallback | F44: D5.3: Calibration service and migration tests | H44: 0.52643052 | I44: =IF(A44=Control!$B$7,Control!$B$11,"")
A45: 42 | B45: 46503 | C45: 46509 | D45: D3.1, D3.2, D5.4 | E45: D3.1: Integrate SX1262 reset, busy, DIO, frequency, power, sleep and wake behavior D3.2: Integrate LoRaWAN OTAA join, uplink, downlink, ADR and retry scheduling D5.4: Verify control timing, boundaries and safe-output states | F45: D3.1: Radio service and radio test logs D5.4: Algorithm, latency and safe-state test report | H45: 0.54277929 | I45: =IF(A45=Control!$B$7,Control!$B$11,"")
A46: 43 | B46: 46510 | C46: 46516 | D46: D3.2, D3.3, D8.2 | E46: D3.2: Integrate LoRaWAN OTAA join, uplink, downlink, ADR and retry scheduling D3.3: Persist frame counters and enforce region/key handling rules D8.2: Define per-device identity, key management, signing, eFuse and debug policies | F46: D3.2: LoRaWAN manager and network-server test evidence | H46: 0.55912807 | I46: =IF(A46=Control!$B$7,Control!$B$11,"")
A47: 44 | B47: 46517 | C47: 46523 | D47: D3.3, D3.4, D8.2 | E47: D3.3: Persist frame counters and enforce region/key handling rules D3.4: Run long-duration join/uplink/downlink stability test D8.2: Define per-device identity, key management, signing, eFuse and debug policies | F47: D3.3: Counter persistence and regional compliance tests D3.4: LoRaWAN endurance report D8.2: Key-management procedure and eFuse/debug plan | H47: 0.57547684 | I47: =IF(A47=Control!$B$7,Control!$B$11,"")
...

Sheet Source & Guidance
A1: Source Mapping and Workbook Guidance
A3: Item | B3: Detail
A4: Source | B4: Uploaded ESP32-S3 Production Firmware Development Lifecycle markdown
A5: Lifecycle hierarchy | B5: Program → Cluster → Phase → Sub-phase → Work package → Deliverable → Exit gate
A6: Owner model | B6: Every task is assigned to Me; no additional resource assumptions
A7: Schedule baseline | B7: Week 1 starts 2026-07-13; production release Week 78; lifecycle baseline ends Week 90
A8: Progress basis | B8: Actual Completion is evidence-based and initialized at 0%
A9: Weighting | B9: Task weight is normalized from duration × complexity (Effort Points)
A10: Dependency notation | B10: Comma-separated predecessor WBS IDs; primarily finish-to-start
A12: Gate Summary
A13: Gate | B13: Week | C13: Required Result | D13: Evidence Row
A14: G-A | B14: 6 | C14: Approved requirements and feasibility | D14: A3.3
A15: G-B | B15: 12 | C15: Reproducible toolchain, repository and CI | D15: B4.3
A16: G-C | B16: 34 | C16: Stable reusable platform baseline | D16: C.G2
A17: G-D | B17: 56 | C17: Complete integrated product features | D17: D.G2
A18: G-E | B18: 70 | C18: Qualified release candidate | D18: E.G1
A19: G-F | B19: 78 | C19: Controlled production release | D19: F4.3 / F.G1
A20: G-G | B20: 90 | C20: Managed lifecycle and closure baseline | D20: G6.2
A22: Definition of Done Applied to Every Work Package
A23: 1 | B23: Requirements/design are identified and documented.
A24: 2 | B24: Interfaces, ownership and error behavior are explicit.
A25: 3 | B25: Implementation is reviewed and CI passes.
A26: 4 | B26: Normal, boundary and failure behavior are tested.
A27: 5 | B27: Resource and security impact are reviewed.
A28: 6 | B28: Evidence is linked or stored and no critical defect remains.
